Workbook

Sheet LEEME
A1: Screening log — Deliverable 4 (Mini systematic review, PRISMA 2020)
A2: Tesis: Verifiable, human-in-the-loop generative AI for contractual clause recommendation (J. Inca Cárdenas)
A4: Hojas
A5: Search_Log: una fila por fuente. Las celdas amarillas las completa el investigador (fecha, string exacto, filtros, total mostrado).
A6: Registros: los 2,910 registros tal como se exportaron, con la columna duplicado_de (ID del registro conservado) y el criterio de deduplicación.
A7: Cribado: los 2,579 registros únicos con etapa, decisión, código y método. Columnas "Verificación" y "Acuerdo" para el control humano.
A8: Otros_metodos: Consensus, SSRN y estudios semilla del D3, cruzados contra las bases.
A9: PRISMA: conteos por casilla del diagrama, calculados con fórmulas a partir de las otras hojas.
A11: Decisiones de protocolo (confirmadas por el investigador)
A12: Conference papers revisados por pares: se incluyen.
A13: Preprints solo en arXiv (sin versión publicada): se excluyen (A1) y se reservan para snowballing.
A14: Consensus y estudios semilla del D3: se reportan en la columna "identificación por otros métodos".
... A47: Revisión humana: se usa la hoja Revision_150 (muestra estratificada de 150 registros, semilla 2026) en lugar de las 403 filas originales; la columna "muestra" de Cribado marca esos 150.

Sheet Revision_150
A1: Revisión humana de una muestra estratificada de 150 registros
A2: Lee título y abstract; responde en "¿De acuerdo?" Sí o No. Si es No, escribe la decisión correcta en Comentario. Criterio: IA generativa (LLM/RAG) + textos legales/contractuales/regulatorios + mide verificabilidad, alucinación o corrección legal.
A3: Revisadas | B3: Acuerdo (Sí) | C3: Desacuerdo (No) | D3: % de acuerdo
A4: =COUNTA(G6:G155) -> 150 | B4: =COUNTIF(G6:G155,"Sí") -> 0 | C4: =COUNTIF(G6:G155,"No") -> 119 | D4: =IFERROR(C4/A4,"") -> 0.79333333
A5: N.º | B5: rec_id | C5: Estrato | D5: Título | E5: Año | F5: Abstract (recortado) | G5: ¿De acuerdo? (Sí/No) | H5: Comentario / decisión correcta
A6: 1 | B6: R2749 | C6: Incluido | D6: A Hybrid Knowledge-Enhanced Legal AI System for Construction Contract Disputes | E6: 2026 | F6: With rapid urbanization and expanding infrastructure, construction contract disputes are increasing in volume and complexity, challenging traditional adjudication. This study proposes a domain-specific legal artificial intelligence (AI) system for construction contract disputes via hybrid knowledge integration based on the retrieval-augmented generation (RAG) paradigm, integrating five core legal texts and 500 adjudication cases within a dual-engine architecture. The knowledge base encodes legal concepts, relations, and rules to enable structured semantic inference. The DeepSeek-R1 reasoning engine analyzes case facts and legal logic via constrained generation, while the BGE-M3 retrieval module matches legal provisions and precedents using multivector indexing. A tripartite evaluation framework—semantic similarity, legal provision citation accuracy, and issue prediction F1 score—validates system performance. The hybrid knowledge model outperforms single-source models, achieving scores of 0.736, 0.952, and 0.937, respectively, while significantly reducing judicial document generation time. This study offers a theoretical and empirical basis for legal AI in Chinese construction disp | G6: SI
A7: 2 | B7: R0082 | C7: Incluido | D7: Measuring Faithfulness and Abstention: An Automated Pipeline for Evaluating LLM-Generated 3-ply Case-Based Legal Arguments | E7: 2025 | F7: Large Language Models (LLMs) demonstrate potential in complex legal tasks like argument generation, yet their reliability remains a concern. Building upon pilot work assessing LLM generation of 3-ply legal arguments using human evaluation, this paper introduces an automated pipeline to evaluate LLM performance on this task, specifically focusing on faithfulness (absence of hallucination), factor utilization, and appropriate abstention. We define hallucination as the generation of factors not present in the input case materials and abstention as the model’s ability to refrain from generating arguments when instructed and no factual basis exists. Our automated method employs an external LLM to extract factors from generated arguments and compares them against the ground-truth factors provided in the input case triples (current case and two precedent cases). We evaluated eight distinct LLMs on three tests of increasing difficulty: 1) generating a standard 3-ply argument, 2) generating an argument with swapped precedent roles, and 3) recognizing the impossibility of argument generation due to lack of shared factors and abstaining. Our findings indicate that while current LLMs achieve h | G7: SI
A8: 3 | B8: R2878 | C8: Incluido | D8: Development of an Automated Construction Contract Review Framework Using Large Language Model and Domain Knowledge | E8: 2025 | F8: Construction contract review demands specialized expertise, requiring comprehensive understanding of both technical and legal aspects. While AI advancements offer potential solutions, two problems exist: LLMs lack sufficient domain-specific knowledge to analyze construction contracts; existing RAG approaches do not effectively utilize domain expertise. This study aims to develop an automated contract review system that integrates domain expertise with AI capabilities while ensuring reliable analysis. By transforming expert knowledge into a structured knowledge base aligned with the SCF classification, the proposed structured knowledge-integrated RAG pipeline is expected to enable context-aware contract analysis. This enhanced performance is achieved through three key components: (1) integrating structured domain knowledge with LLMs, (2) implementing filtering combined with hybrid dense–sparse retrieval mechanisms, and (3) employing reference-based answer generation. Validation using Oman’s standard contract conditions demonstrated the system’s effectiveness in assisting construction professionals with contract analysis. Performance evaluation showed significant improvements, achiev | G8: SI
A9: 4 | B9: R0679 | C9: Incluido | D9: LegalBot-EC: An LLM-Based Chatbot for Legal Assistance in Ecuadorian Law | E9: 2025 | F9: This work presents LegalBot-EC, a domain-specific legal chatbot designed to provide accurate responses grounded in Ecuadorian law. The system combines ChromaDB for contextual retrieval and LLaMA 3.1 as its generative model, ensuring legally relevant and contextually grounded answers. Its knowledge base consists of two key legal documents, the COIP and the 2008 Constitution of Ecuador, which serve as the foundation for response generation. The chatbot was evaluated through two key assessments: user satisfaction and accuracy measurement. A satisfaction study conducted with final-year university students specializing in law resulted in an average score of 88.72 out of 100, indicating strong approval in terms of correctness, relevance, and clarity. Additionally, an accuracy assessment based on 25 legal queries demonstrated robust performance, with 23 correct responses, 2 partially correct responses, and none classified as incorrect, yielding a weighted accuracy of 96%. Furthermore, qualitative tests confirm the chatbot’s ability to generate well-structured, legally sound responses, even when queried in English, demonstrating multilingual capabilities. | G9: SI
A10: 5 | B10: R0102 | C10: Incluido | D10: A Rule-Guided Retrieval-Augmented Framework for Intelligent Contract Review Based on Clause-Type Classification | E10: 2026 | F10: Large language models (LLMs) have shown potential in legal text processing, but direct LLM-based contract review remains limited by hallucinated findings, unstable rule matching, redundant outputs, and weak traceability. This paper proposes a rule-guided retrieval-augmented framework for intelligent contract review based on clause-type classification. The framework segments contracts into clause-level units, classifies each clause into predefined types, retrieves audit rules through clause-type filtering, keyword matching, semantic retrieval, and reranking, and generates traceable review findings with revision suggestions. A human-in-the-loop mechanism is introduced to support professional oversight and reduce unsupported conclusions. A pilot evaluation on equipment procurement and sales contracts compares the proposed method with DeepSeek-only and vanilla RAG baselines. The results indicate that clause-type-guided retrieval improves audit rule matching, enhances risk detection, reduces redundant findings, and strengthens the traceability of generated outputs. This study provides a practical and explainable approach for applying LLMs to legal contract review. | G10: SI
A11: 6 | B11: R0016 | C11: Incluido | D11: A New Metadata-Aware Retrieval-Augmented Generation (RAG) Architecture for Trustworthy Legal Question Answering | E11: 2026 | F11: Large Language Models (LLMs) offer strong capabilities for Natural Language Processing, yet their inherent uncertainty often produces hallucinations, confident but incorrect statements, which is critical in domains requiring precise knowledge representation. Retrieval-Augmented Generation (RAG) reduces this risk through information retrieval, but standard pipelines still suffer from fragmented context and weak alignment between queries and legal provisions, limiting trustworthy knowledge extraction. This study proposes a Metadata-Aware RAG architecture to improve grounding in large legal corpora. It integrates: 1) Sub-chunking with Legal Metadata Inheritance, which transforms unstructured legal PDFs into granular, metadata-rich fragments; and 2) an Adaptive Filter Creator, a pipeline that extracts structured constraints and compiles optimized hybrid retrieval queries. These components enhance semantic alignment, reduce uncertainty-driven hallucinations, and strengthen neural information retrieval. Using a curated Peruvian labor law corpus and 150 manually validated question–answer pairs, the system was evaluated across three LLMs (Llama-3.1-8B, GPT-OSS-20B, Gemma-3-27B). The propos | G11: SI
A12: 7 | B12: R0052 | C12: Incluido | D12: Hallucination-Free? Assessing the Reliability of Leading AI Legal Research Tools | E12: 2025 | F12: Legal practice has witnessed a sharp rise in products incorporating artificial intelligence (AI). Such tools are designed to assist with a wide range of core legal tasks, from search and summarization of caselaw to document drafting. However, the large language models used in these tools are prone to “hallucinate,” or make up false information, making their use risky in high-stakes domains. Recently, certain legal research providers have touted methods such as retrieval-augmented generation (RAG) as “eliminating” or “avoid[ing]” hallucinations, or guaranteeing “hallucination-free” legal citations. Because of the closed nature of these systems, systematically assessing these claims is challenging. In this article, we design and report on the first preregistered empirical evaluation of AI-driven legal research tools. We demonstrate that the providers' claims are overstated. While hallucinations are reduced relative to general-purpose chatbots (GPT-4), we find that the AI research tools made by LexisNexis (Lexis+ AI) and Thomson Reuters (Westlaw AI-Assisted Research and Ask Practical Law AI) each hallucinate between 17% and 33% of the time. We also document substantial differences bet | G12: SI
A13: 8 | B13: R2698 | C13: Incluido | D13: Long-Document RAG for Contractual and Insurance Clause Analysis in Receivables RWA Structures | E13: 2024 | F13: Receivables real-world-asset (RWA) structures require repeated verification of master receivables purchase agreements, insurance policies, repurchase language, default triggers, and dilution-risk provisions. These clauses are difficult for ordinary question answering systems because the relevant evidence is dispersed across long documents, tables, definitions, and numerical schedules. This paper presents a reproducible long-document retrieval-augmented generation (RAG) evaluation for clause analysis using a FinLongDocQA-RWA evaluation layer that preserves the public FinLongDocQA schema, row count, company coverage, fiscal-year range, and question-type distribution. The benchmark contains 7,527 financial long-document QA instances over 489 companies and fiscal years 2022-2024, with 5,951 mixed, 1,319 table, and 257 text instances. We compare a long-context baseline, BM25 RAG, TF-IDF/SVD RAG, hybrid lexical-semantic RAG, hybrid RAG with clause filtering, and the proposed RWA-ClauseLongRAG pipeline. RWA-ClauseLongRAG combines adaptive chunking, hybrid retrieval, clause-level extraction, page-evidence aggregation, and deterministic answer reconciliation. Across all 7,527 instances, it | G13: SI
A14: 9 | B14: R0021 | C14: Incluido | D14: Grounded in Law: A Multi-Stage Anti-Hallucination Pipeline for Legal RAG Systems in Brazilian Portuguese | E14: 2026 | F14: Large Language Models (LLMs) are effective text generators but create legal citations at non-trivial rates, a failure mode with serious consequences in legal practice. In Brazilian Portuguese the risk is amplified by citation variability (juridiquês), fragment-level references (article → paragraph → item), and the need to distinguish jurisdictions and court instances. We describe EscavAI, a production Retrieval-Augmented Generation (RAG) system deployed at Escavador, a Brazilian legal-technology platform. The system combines (1) domain-tuned hybrid retrieval (lexical, dense, and cross-encoder reranking) over a large-scale legal corpus; (2) grounded generation with explicit citation constraints; and (3) a post-generation Reference Audit layer that extracts legislation and jurisprudence mentions via specialized taggers, normalizes them to a canonical schema, checks existence against authoritative databases at fragment granularity, verifies fidelity against official texts, and triggers targeted rewrites when inconsistencies are detected. We report production telemetry from 184,895 audited answers containing 43,175 extracted legal references. Legislation references resolve at 81.7%, wh | G14: SI
A15: 10 | B15: R0037 | C15: Elegibilidad E7 | D15: Precedent Aware Legal Reasoning System for Turkish Jurisdiction with RAG Supported LLMs | E15: 2025 | F15: Large Language Models have achieved impressive progress in natural language processing, yet their tendency to hallucinate undermines reliability in high-stakes domains such as law. This paper presents a precedent-grounded Retrieval-Augmented Generation framework for legal question answering in the Turkish judicial system. The framework integrates dense retrieval with domain-tuned embeddings and sparse retrieval with BM25 and introduced two domain-adapted models: LexiTurk111M for retrieval and LexiTurk-14B for generation. Compared to strong baselines, the system delivers clear gains in retrieval accuracy, answer correctness, and faithfulness, while substantially reducing hallucinations. In particular, LexiTurk14B outperforms its base Qwen3-14B, with correctness increasing from 2.10 to 3.10 in closed-book and 4.23 with RAG. These results highlight the effectiveness of precedent-grounded RAG and establish a reproducible path toward explainable and trustworthy legal AI in under-resourced languages. © 2025 IEEE. | G15: SI
A16: 11 | B16: R0471 | C16: Elegibilidad E7 | D16: Detecting Transitional Provisions in EU Legislation with Hybrid AI for Better Regulation | E16: 2025 | F16: Maintaining an accessible and up-to-date legislative framework is crucial for ensuring transparent governance and enabling effective citizen participation in democratic processes. This paper examines methodological approaches for the automated detection and modeling of textual modifications within EU Regulations and Directives, with particular attention to transitional provisions and temporal concepts (retroactivity, postponement, relative dates), as well as legislative ones (entry into force, application, sunset clause). We present a comparative analysis of four distinct approaches: (1) a rule-based pipeline utilizing regular expressions to capture standardized legal expressions, (2) a SpaCy-based pipeline leveraging advanced NLP capabilities for entity recognition and pattern matching, (3) a Large Language Model (LLM)-based pipeline using the OpenRouter API for contextual extraction, and (4) RDF/Cellar extraction serving as the benchmark. Each methodology is designed to generate standardized Akoma Ntoso (AKN) metadata annotations, facilitating point-in-time understanding of legislative modifications and temporal validity. The rule-based and SpaCy-based approaches offer computatio | G16: SI
A17: 12 | B17: R0468 | C17: Elegibilidad E7 | D17: Evidence-First Structured Generation: A Two-Stage "Extract-Generate" Minimization Framework for Power Regulation Question Answering | E17: 2025 | F17: The auditability and reproducibility of answers are vital for safety and compliance in power regulation question answering. However, current approaches often lack evidence traceability, involve high costs in fine-tuning and deploying large models, and exhibit poor format adaptability. To overcome these limitations, we introduce an Evidence-First, two-stage extract-generate framework. Its first stage employs a dual-track retrieval strategy combining BM25 and vector retrieval to obtain candidate clauses, from which a fine-tuned model extracts key evidence snippets. These extracted snippets, along with associated metadata including clause numbers, versions, source URLs and confidence scores, are passed to the second stage. The second stage uses predefined templates to integrate this evidence with metadata for structured answer generation. Utilizing LORA for parameter-efficient fine-tuning, the framework updates only a minimal fraction of parameters, creating a stable retrieve-extract-generate loop. Experiments on 1069 power regulations and a DuReader-robust subset show our method achieves 88.7% evidence completeness and 89.3% format consistency under comparable resources, outperformin | G17: SI
... A47: 42 | B47: R0122 | C47: Elegibilidad E6 | D47: Verifiable Legal Contract Question Answering Using Natural Language Inference Grounding and Knowledge Graphs | E47: 2026 | F47: Legal contract analysis is a critical yet labor-intensive process in the legal and business domains where precise interpretation of complex contractual language is required. Existing approaches to automated legal question answering (QA) suffer from hallucination, lack of verifiability, and inability to provide traceable reasoning. This work provides a hybrid neural and structured-verification pipeline that combines retrieval-augmented generation with multi-signal verification to produce accurate, verifiable answers from legal contracts. This system integrates a FAISS-based semantic retrieval engine using Sentence Transformers for clause-level retrieval, a Qwen 2.5-7B language model fine-tuned with Supervised Fine-Tuning (SFT) for structured legal tool-calling reasoning and fine-tuned DeBERTa-v3 Natural Language Inference (NLI) model for verification. The pipeline concludes with confidence gating that flags low-confidence answers, preventing silent hallucination. | G47: No
A48: 43 | B48: R2350 | C48: No recuperado | D48: Generative AI Hallucinations and Legal Liability in Jordanian Civil Courts: Promoting the Responsible Use of Conversational Chat Bots | E48: 2024 | G48: No
A49: 44 | B49: R2659 | C49: No recuperado | D49: Automate Text Processing for Schematically Analyzing Legal Texts | E49: 2024 | G49: No
A50: 45 | B50: R1847 | C50: Cribado E3 (manual) | D50: Green Industrial Policy and Sustainable Development in Emerging Markets: A Multi-Agent Decision-Support System with International-Law Source Ranking for Evidence-Grounded Cross-Border Green Product Requirements | E50: 2026 | F50: Emerging-market exporters encounter global sustainability governance not as a treaty or a target but as a product rule: an energy performance threshold, a restricted-substance limit, and a recyclability declaration. Those rules are published, and publication is not the same as access. A firm with a regulatory affairs department can establish which version of a measure is in force, which products it covers and what evidence the destination market will accept; the small- and medium-sized enterprises that dominate emerging-market export bases usually cannot, so rules written to raise environmental standards can exclude the firms least equipped to read them. This paper asks whether emerging digital technologies can convert the transparency infrastructure of the trading system into sustainable business capability. We develop GRACE, a WTO-informed decision-support system that resolves regulatory versions and timelines before interpretation begins, ranks evidence by the authority of its source, declines to state any obligation that no official passage supports, and escalates to human experts when the record is incomplete. Evaluation covers 214 held-out notification families under family-l | G50: No
A51: 46 | B51: R1529 | C51: Cribado E3 (manual) | D51: Governance of Generative AI | E51: 2025 | F51: The rapid and widespread diffusion of generative artificial intelligence (AI) has unlocked new capabilities and changed how content and services are created, shared, and consumed. This special issue builds on the 2021 Policy and Society special issue on the governance of AI by focusing on the legal, organizational, political, regulatory, and social challenges of governing generative AI. This introductory article lays the foundation for understanding generative AI and underscores its key risks, including hallucination, jailbreaking, data training and validation issues, sensitive information leakage, opacity, control challenges, and design and implementation risks. It then examines the governance challenges of generative AI, such as data governance, intellectual property concerns, bias amplification, privacy violations, misinformation, fraud, societal impacts, power imbalances, limited public engagement, public sector challenges, and the need for international cooperation. The article then highlights a comprehensive framework to govern generative AI, emphasizing the need for adaptive, participatory, and proactive approaches. The articles in this special issue stress the urgency of d | G51: No
A52: 47 | B52: R0344 | C52: Cribado E3 (manual) | D52: TSAC-RAG: Type- and Structure-Aware Constraint Retrieval for Question Answering over Power-System Standards | E52: 2026 | F52: Power-system technical standards provide the engineering basis for substation design, equipment acceptance, operation and maintenance, relay protection, and grid security control. Large language models (LLMs) offer a convenient interface to this knowledge, but their answers may be unreliable when requirements vary with equipment type, voltage level, operating condition, numerical limit, physical unit, or clause scope. This paper proposes TSAC-RAG, a type- and structure-aware retrieval-augmented generation framework for question answering over power-system standards. It combines lexical relevance, numerical–unit consistency, clause hierarchy, and question-type information to retrieve and rerank applicable clauses. The evidence is then supplied to an instruction-tuned LLM for engineering interpretation and citation-grounded answer generation. An audit of EleQA identifies 31,181 nonempty clauses and 18,584 questions with exact evidence mappings. Across three balanced test samples, TSAC-RAG achieves 83.82 ± 0.54% Recall@1, 96.81 ± 0.03% Recall@10, and 88.73 ± 0.28% MRR@10, improving over the strongest unconstrained retriever by 1.31, 0.50, and 1.11 percentage points. The results show t | G52: No
A53: 48 | B53: R0960 | C53: Cribado E3 (manual) | D53: RAIM: Operationalizing Trustworthy AI in Music Generation | E53: 2026 | F53: Generative AI is radically reshaping the musical landscape, unlocking new forms of creative expression while simultaneously raising profound ethical, legal, and societal concerns. Key among these are the potential displacement of human creativity, copyright infringement stemming from vast training datasets, and the lack of transparency, explainability, and fairness mechanisms. As generative systems become pervasive, shifting from reactive regulation to responsible design is crucial. While previous work has tackled isolated aspects of generative systems, we propose a systematic framework grounded in the Ethics Guidelines for Trustworthy AI produced by the European Commission’s High-Level Expert Group. Focusing on generative music AI, we contextualize these requirements into 45 responsible features that address trustworthiness across technical, legal, and artistic dimensions. We evaluate this framework through a multi-stage Delphi study involving a global panel of experts from academia, industry, and regulatory bodies, comprising AI ethicists, legal experts, music AI practitioners, and artists. The results demonstrate a high degree of expert endorsement for the proposed features, whi | G53: No
A54: 49 | B54: R1915 | C54: Cribado E3 (manual) | D54: Should I and Can I Use AI for Forensic Psychiatry Report Writing? | E54: 2026 | F54: Abstract The rapid evolution of AI, particularly large language models (LLMs), has renewed interest in their potential role in forensic psychiatry report writing. Recent evidence demonstrates that contemporary LLMs perform well in selected medical knowledge, documentation, and information management tasks and may reduce the administrative burden when deployed under appropriate clinical supervision. However, forensic psychiatric reports differ fundamentally from routine clinical documentation. They constitute expert evidence prepared for legal proceedings and therefore require transparent reasoning, explicit weighing of competing evidence, a robust factual foundation, and personal professional accountability. This viewpoint examines whether AI can and should be used in forensic psychiatry report writing by integrating recent empirical evidence, forensic psychiatry guidance, legal and regulatory frameworks, and emerging governance recommendations. Rather than comparing AI with an idealized human evaluator, the manuscript argues that the appropriate comparison is between 2 imperfect systems of reasoning. Human experts remain susceptible to cognitive biases, omission errors, and disagr | G54: No
A55: 50 | B55: R0223 | C55: Cribado E3 (manual) | D55: Rethinking Strategic Mechanism Design in the Age of Large Language Models: New Directions for Communication Systems | E55: 2025 | F55: This paper explores the application of large language models (LLMs) in designing strategic mechanisms -including auctions, contracts, and games- for specific purposes in communication networks. Traditionally, strategic mechanism design in telecommunications has relied on human expertise to craft solutions based on game theory, auction theory, and contract theory. However, the evolving landscape of telecom networks, characterized by increasing abstraction, emerging use cases, and novel value creation opportunities, calls for more adaptive and efficient approaches. We propose leveraging LLMs to automate or semi-automate the process of strategic mechanism design, from intent specification to final formulation. This paradigm shift introduces both semi-automated and fully-automated design pipelines, raising crucial questions about faithfulness to intents, incentive compatibility, algorithmic stability, and the balance between human oversight and artificial intelligence (AI) autonomy. The paper discusses potential frameworks, such as retrieval-augmented generation (RAG)-based systems, to implement LLM-driven mechanism design in communication networks contexts. We examine key challenges, | G55: No
A56: 51 | B56: R2821 | C56: Cribado E3 (manual) | D56: RESPONSIBLE USE OF AI-GENERATED CONTENT IN VIETNAMESE SCHOLARLY PUBLISHING: EVIDENCE FROM JOURNAL POLICIES AND EDITORIAL PRACTICES | E56: 2026 | F56: The rapid diffusion of generative artificial intelligence (GenAI) tools—especially large language models (LLMs)—is reshaping scholarly publishing worldwide. While these tools can support language editing, translation, and workflow efficiency, they also raise integrity risks, including fabricated citations, unverifiable claims, undisclosed ghostwriting, confidentiality breaches in peer review, and contested ownership of AI-assisted outputs. Vietnam’s journal ecosystem is currently navigating internationalization pressures (e.g., indexing and visibility goals) alongside uneven editorial capacity and fragmented policy infrastructure, making it a critical setting for examining responsible governance of AI-generated content (AIGC). This study reports an exploratory policy-and-practice mapping across five Vietnam-affiliated publishing contexts (university-based open access journals, an internationally co-published journal, a defense-related journal, and law/social-science publishing). Using structured qualitative content analysis, we identify shared norms (e.g., “AI cannot be an author,” accountability remains human) but also substantial variation in disclosure requirements, treatment of | G56: No
A57: 52 | B57: R2884 | C57: Cribado E3 (manual) | D57: A Spatiotemporal–Semantic Coupling Intelligent Q&A Method for Land Use Approval Based on Knowledge Graphs and Intelligent Agents | E57: 2025 | F57: The rapid retrieval and precise acquisition of land use approval information are crucial for enhancing the efficiency and quality of land use approval, as well as for promoting the intelligent transformation of land use approval processes. As an advanced retrieval method, question-answering (Q&A) technology has become a core technical support for addressing current issues such as low approval efficiency and difficulty in obtaining information. However, existing Q&A technologies suffer from significant hallucination problems and limitations in considering spatiotemporal factors in the land use approval domain. To effectively address these issues, this study proposes a spatiotemporal–semantic coupling intelligent Q&A method for land use approval based on knowledge graphs (KGs) and intelligent agent technology, aiming to enhance the efficiency and quality of land use approval. Firstly, a land use approval knowledge graph (LUAKG) is constructed, systematically integrating domain knowledge such as policy clauses, legal regulations, and approval procedures. Then, by combining large language models (LLMs) and intelligent agent technology, a spatiotemporal–semantic coupling Q&A framework i | G57: No
A58: 53 | B58: R1475 | C58: Cribado E3 (manual) | D58: Repairing DeFi Vulnerabilities: Benchmarking LLMs with Executable Solidity Exploits | E58: 2025 | F58: Decentralized finance protocols are frequently exploited, creating a demand for fast and reliable repair of vulnerable smart contracts and validation that reflects runtime security. Large language models are an emerging source of patches, yet many evaluations rely on manual checks or self-assessment, which cannot confirm whether attacker profit is actually prevented. We introduce an executable benchmark that replays verified real-world exploits against patched Solidity contracts under a resilient protocol that permits alternate attack paths and controlled state variation. Our framework compiles candidate patches, deploys them on a forked chain, and tests whether the exploit still yields profit. The benchmark covers six test cases drawn from reproducible incidents and is released as open-source. Among the nine evaluated models, GPT-5, GPT-4.1, and Claude Opus 4.1 performed the best, mitigating four of six test cases. Microsoft Phi-4 was the most reliable open-source model, mitigating two of six exploits and producing compilable patches for the remaining cases. No model mitigated the H2O case once resilient checks were enabled, while a simpler access control flaw, BTNFT, was often re | G58: No
A59: 54 | B59: R2708 | C59: Cribado E3 (manual) | D59: A Human-in-the-Loop LLM Agent Framework with LoRA Domain Adaptation for DO-330 TQL-1 Tool Qualification | E59: 2026 | F59: Civil airborne software certification follows RTCA/DO-178C, and tools used in its development and verification must be qualified per RTCA/DO-330. For TQL-1 tools—the highest qualification level—the strict criteria, the demand for detailed process data, and the substantial peer-review effort have become important factors driving program duration and human cost; at the same time, TQL-1 requires verification activities to reach Independence Level 3, which makes fully replacing manual review with AI infeasible on compliance grounds. To safely introduce AI assistance under these airworthiness constraints, we propose a Human-in-the-Loop (HITL) LLM-Agent framework that delegates highly repetitive, rule-bounded compliance pre-screening to the Agent while keeping independent judgment and formal sign-off with human reviewers. The framework comprises three components: (1) a rule-extraction chain that uses DeepSeek-R1 671B to convert project-level TRS/TDS/TCS into a JSON rule set with source-clause-ID provenance; (2) LoRA domain adaptation that applies QLoRA 4-bit fine-tuning to Qwen3-Coder-30B-A3B on a three-source dataset (DeepSeek-R1 distilled synthesis, commercial static-analyzer hits, and | G59: No
A60: 55 | B60: R2791 | C60: Cribado E3 (manual) | D60: Benchmarking large language models for ACMG/AMP variant interpretation and variant calling | E60: 2026 | F60: Agentic large language models are increasingly used across the genomic workflow, from variant calling to clinical interpretation, yet they are evaluated by accuracy alone, a single figure that cannot say whether a system is safe or where in the workflow a failure originates. We present ClawBench, a framework that attributes each outcome to the architectural layer that produced it across both halves of the canonical pipeline. Two design choices remove the confounds that make agentic genomics hard to evaluate: a temporally blinded truth set, in which every scored ClinVar label first became available only after the training cutoff of every model tested, and a fail-closed evidence contract that blocks evidence circular with the truth label. We score validity, safety, provenance and reproducibility, not accuracy alone, under a constraint gradient that relocates correctness from a model’s prior into executed, validated code. We show three things. First, dangerous misclassification is rare and model-invariant, a controlled precondition of the executed architecture rather than a frontier, while fabricated evidence is measurable and is neutralised by execution. Second, different variant cla | G60: No
A61: 56 | B61: R2496 | C61: Cribado E3 (manual) | D61: SafeDep: Detecting State Mutation Unsoundness in Rust via Dependency Slicing and LLM Reasoning | E61: 2026 | F61: Rust's type system protects safe code, but many low-level abstractions depend on internal unsafe operations whose correctness rests on memory and logical invariants. In struct-based abstractions, a sibling method may legally modify internal fields while invalidating a precondition required by another method's unsafe operation. We call this defect an unsound state mutation. Traditional pattern-based static analyzers support inter-procedural tracking but may lack the capability to model cross-method state interference. Furthermore, they cannot interpret natural-language safety contracts, making these deep defects difficult to detect. LLMs can reason about these contracts, but whole-crate prompting is expensive and often prone to hallucinated paths. To bridge this gap, we present SafeDep, a vulnerability discovery framework that combines compiler-driven static analysis with LLM-based semantic reasoning. SafeDep analyzes Rust MIR to build a field-sensitive read/write dependency graph and slices the graph to retain methods that may affect safety-critical state. An LLM then reconstructs cross-method state transitions from this compact context and generates PoC candidates. A bounded compi | G61: No
... A79: 74 | B79: R1634 | C79: Cribado E3 (regla) | D79: Potential Use of ChatGPT-4 in Micronutrient Deficiency Management: A Narrative Scoping Review and a Framework for Validation and Safe Deployment | E79: 2026 | F79: Abstract / Summary Micronutrient deficiencies remain common and clinically important, yet their recognition and management require careful history-taking, appropriate testing, and guideline-concordant counseling. Large language models (LLMs) such as ChatGPT-4 have been proposed as tools that may support clinical nutrition workflows; however, their capabilities and limitations are frequently misunderstood, and their safe use requires rigorous validation. This article provides a narrative scoping synthesis of plausible use cases for ChatGPT-4 across micronutrient deficiency care (e.g., structured symptom–diet–medication history elicitation, drafting clinician-facing summaries, and preparing patient education materials) while explicitly noting that ChatGPT-4 is not an autonomous diagnostic system, does not access real-time biomedical databases, and cannot replace clinician judgment. The authors then propose a practical framework for validation and safe deployment, including task definitions, standardized prompt templates, comparison baselines (clinician-authored outputs and rule-based checklists, and where appropriate predictive machine learning [ML] models), clinician annotation with | G79: No
A80: 75 | B80: R1617 | C80: Cribado E3 (regla) | D80: OntoMetric: An Ontology-Guided Framework for Automated ESG Knowledge Graph Construction | E80: 2025 | G80: No
A81: 76 | B81: R0572 | C81: Cribado E3 (regla) | D81: A Hierarchical Verification Framework for Power Engineering Design Based on LLM-Driven Rule and Knowledge Base Integration | E81: 2025 | F81: This paper presents a hierarchical design verification framework that integrates Large Language Models with structured engineering knowledge to automate power system design validation. The framework employs a three-layer architecture: rule-based compliance checking, technical consistency analysis, and completeness assessment. The system leverages formalized rules from IEEE/IEC standards and maintains citation-backed rationales linking verification decisions to authoritative sources. A case study on a real-world 220 kV substation design project demonstrates the framework's practical applicability, achieving expert-validated 92% accuracy in issue identification across 156 pages of design documentation. The system successfully detected all major compliance issues including protection coordination violations and equipment rating inconsistencies, while identifying additional optimization opportunities. | G81: No
A82: 77 | B82: R0554 | C82: Cribado E3 (regla) | D82: ArgRE: Formal Argumentation for Conflict Resolution in Multi-Agent Requirements Negotiation | E82: 2026 | F82: As software systems grow in complexity, they must satisfy an increasing number of competing quality attributes, making it essential to balance them in a principled manner—for example, a safety requirement for sensor-fusion verification may conflict with a tight planning-cycle budget. Multi-agent large language model frameworks support this balancing process by assigning specialized agents to different objectives. However, their conflict resolution is typically heuristic. Requirements are aggregated implicitly without explicit acceptance or rejection, limiting auditability in regulated domains. We present ArgRE, a multi-agent requirements negotiation system that embeds Dung-style abstract argumentation into the negotiation stage. Each proposal, critique, and refinement is modeled as an argument, conflicts are represented as directed attack relations, and the accepted set of arguments is computed under grounded and preferred semantics. The pipeline further integrates KAOS goal modeling, multi-layer verification, and standards-oriented artifact generation. Evaluation across five case studies spanning safety-critical, financial, and information-system domains shows that ArgRE provides | G82: No
A83: 78 | B83: R0883 | C83: Cribado E3 (regla) | D83: BLIND-TWIN: Blockchain-Assisted LLM-Based Cds for Digital Twin-Enhanced Industrial AIoT | E83: 2025 | F83: The interconnected and diverse nature of Digital Twin (DT)-based industrial Artificial Internet of Things (AIoT) systems exposes them to potential cyber threats and malicious activities. This paper introduces a novel framework called BLIND-Twin, which leverages blockchain, DT, and Large Language Model (LLM) technologies to address critical security and scalability challenges in industrial AIoT networks. By integrating DT technology, BLIND-Twin continuously mirrors physical environments, enabling real-time monitoring and synthetic data generation to simulate diverse threat scenarios. Data from the DT undergoes feature extraction via a Long Short-Term Memory (LSTM) Autoencoder (LSTM-AE) to extract essential temporal patterns, while the LLM enables adaptive, contextaware intrusion detection without retraining. A permissioned blockchain layer ensures data integrity, privacy, and secure logging through smart contracts, supporting automated threat response with verifiable audit trails. The framework's decentralized architecture mitigates Single Points of Failure (SPoF), addressing scalability and privacy concerns. Performance evaluations utilizing datasets like 5G-NIDD and CICIoT2023 dem | G83: No
A84: 79 | B84: R0680 | C84: Cribado E3 (regla) | D84: Traceability and Performance Optimization: Application of Generative AI, Digital Twin, and DRL in the Recycling Process of WEEE | E84: 2024 | F84: The lack of transparency, unified standards, and effective regulation, along with the complexity of the supply chain, make it challenging to achieve reliable traceability throughout the entire process of recycling and reusing waste electronic appliances. This poses a challenge for effectively implementing carbon reduction measures. In response to the above issues, we propose a full process data management solution for WEEE recycling based on blockchain technology. In addition, a method combining digital twin and generative AI technology has been proposed to address the performance bottleneck issue of blockchain. Predicting future data flow through generative AI models and utilizing reinforcement learning algorithms to predictively optimize blockchain parameter configurations effectively improve blockchain performance and scalability. The experimental results demonstrate that the proposed method effectively enhances system adaptability and throughput. It achieves an integration of reliable traceability, accurate prediction, and performance optimization throughout the entire process of WEEE recycling and reuse data management. | G84: No
A85: 80 | B85: R0847 | C85: Cribado E3 (regla) | D85: Cognitive Security Risks and Countermeasures of Generative Artificial Intelligence in Education Management | E85: 2026 | F85: Generative artificial intelligence (GenAI) is rapidly transforming education management through advanced content generation, reasoning, and autonomous decision-support capabilities. While these technologies promise significant gains in efficiency, personalization, and scalability, their deployment also introduces a class of cognitive security risks that extend beyond traditional cybersecurity and data privacy concerns. These risks directly affect human cognition, judgment, learning integrity, and institutional governance, yet remain insufficiently systematized in existing research. This paper presents a comprehensive analysis of cognitive security in GenAI-enabled education management from a socio-technical and engineering management perspective. We propose a three-tiered taxonomy that categorizes risks into 1) internal security (model vulnerabilities such as jailbreaks, backdoors, and data poisoning), 2) interactional security (hallucination, bias, data leakage, and intellectual property infringement arising from human–AI interaction), and 3) external security (the weaponization of GenAI for fraud, disinformation, deepfakes, and malicious automation). Building on this taxonomy, we | G85: No
A86: 81 | B86: R2200 | C86: Cribado E3 (regla) | D86: Applications of DeepSeek in Medicine: Bibliometric Analysis and Scoping Review | E86: 2026 | F86: Abstract Background The integration of large language models (LLMs) into medicine has reshaped health care delivery, education, and research. Although proprietary models face challenges such as data privacy, regulation, and adaptability, DeepSeek, an open-source LLM, has emerged as a customizable and cost-effective alternative with significant potential for clinical and operational applications. However, the rapid expansion of research in this area necessitates a systematic mapping of its landscape, applications, and challenges. Objective This study combines bibliometric analysis with a scoping review to systematically map and characterize the literature on DeepSeek’s medical applications. The aims were to (1) analyze publication trends, leading contributors, and research themes and (2) identify primary application domains, strengths, limitations, and future directions. Methods Following the framework by Arksey and O’Malley and the PRISMA-ScR (Preferred Reporting Items for Systematic Reviews and Meta-Analyses Extension for Scoping Reviews) guidelines, a systematic search was conducted using PubMed, Web of Science, and Scopus from January 20, 2025, to November 30, 2025. Bibliometric | G86: No
...

Sheet Search_Log
A1: Fuente | B1: Fecha de búsqueda | C1: String exacto ejecutado | D1: Campos / filtros | E1: Total mostrado por la plataforma | F1: Registros exportados (fórmula) | G1: Columna PRISMA | H1: Nota
A2: Scopus | B2: 18/10/2026 | C2: TITLE-ABS-KEY(...) AND PUBYEAR > 2019 AND PUBYEAR < 2027 | D2: Título, abstract, keywords | E2: 100 | F2: =COUNTIF(Registros!B:B,"Scopus") -> 100 | G2: Bases de datos | H2: Total confirmado por el investigador (100).
A3: IEEE Xplore | B3: 18/10/2026 | C3: ("All Metadata":...) — pegar string final | D3: All Metadata; año 2020–2026 | E3: 907 | F3: =COUNTIF(Registros!B:B,"IEEE Xplore") -> 907 | G3: Bases de datos | H3: Confirmar si se corrió con regulat* o con la versión restringida.
A4: Semantic Scholar | B4: 18/10/2026 | C4: bulk search: (...)+(...)+(...) | D4: Título, abstract; year=2020- | E4: 1903 | F4: =COUNTIF(Registros!B:B,"Semantic Scholar") -> 1903 | G4: Bases de datos | H4: Incluye registros de arXiv y ACL Anthology.
A5: SciELO | B5: 18/10/2026 | C5: ("modelo de lenguaje" OR "modelos de lenguaje" OR "inteligencia artificial generativa" OR "IA generativa" OR "generación aumentada por recuperación" OR LLM OR RAG OR ChatGPT OR "large language model" OR "generative AI" OR "retrieval-augmented generation") AND (atribuci$ OR cita$ OR verificab$ OR alucinaci$ OR trazab$ OR fundamentaci$ OR attribution OR citation$ OR hallucination$ OR grounding OR faithfulness OR traceab$) AND (contrat$ OR cláusula$ OR clausula$ OR fideicomiso$ OR fiduciari$ OR regulaci$ OR contract$ OR clause$ OR regulat$) | D5: Todos los índices; sin filtros | E5: 3 | F5: =COUNTIF(Registros!B:B,"SciELO") -> 3 | G5: Bases de datos | H5: Prueba piloto previa (sin comillas ni bloque de dominio) devolvió 0; se corrigió la sintaxis antes de la búsqueda final. La exportación no incluye abstracts.
A6: Web of Science | B6: 18/10/2026 (intento) | C6: TS=(("large language model*" OR LLM OR "generative AI" OR "retrieval-augmented generation" OR RAG) AND (attribut* OR citation* OR verifiab* OR hallucinat* OR grounding OR faithfulness OR traceab*) AND (contract* OR clause* OR "legal drafting" OR regulat* OR fiduciar*)) AND PY=(2020-2026) | D6: Core Collection; TS = título, abstract, keywords | E6: No ejecutado | F6: No ejecutado | G6: Bases de datos | H6: No ejecutado: sin acceso institucional (la cuenta personal solo habilita la búsqueda de investigadores). String preparado y documentado para la revisión doctoral completa; se declara como limitación.
A7: SSRN | B7: 18/10/2026 | C7: Consultas cortas (una fila por consulta) | D7: Title, Abstract & Keywords | E7: 2 | G7: Otros métodos | H7: 2 resultados; ambos registrados en Otros_metodos.
A8: Consensus | B8: 18/10/2026 | E8: 20 | G8: Otros métodos | H8: Buscador con IA; no reproducible con string booleano. c2_report es subconjunto de C_report.
A9: Estudios semilla D3 | C9: — | D9: — | E9: 5 | G9: Otros métodos | H9: Magesh 2025, Wang 2025, Wallat 2025, Ju & Lee 2026, Narayanan & Singh 2026.

Sheet Registros
A1: rec_id | B1: fuente | C1: id_fuente | D1: titulo | E1: autores | F1: anio | G1: venue | H1: tipo | I1: doi | J1: arxiv | K1: duplicado_de | L1: criterio_dup | M1: abstract
A2: R0001 | B2: Scopus | C2: 2-s2.0-105045454948 | D2: Beyond Accuracy: Evaluating LLMs for Evidentiary Use in Legal Contexts | E2: Narayanan S.; Potel M.; Mithal V. | F2: 2026 | G2: Artificial Intelligence and Legal Evidence: The Indian Policy and Perspective | H2: Book chapter | I2: 10.1201/9781003629146-2 | M2: Large Language Models (LLMs) are increasingly reshaping the legal domain, presenting substantial potential for various tasks, including legal research, judgment “prediction,” and document drafting. Although specialized/domain-specific LLMs and Retrieval-Augmented Generation (RAG) are designed to enhance performance, general-purpose LLMs demonstrate significant limitations, such as a deficiency in specialized legal knowledge, vulnerability to “hallucinations,” and the perpetuation of biases inherent in training data. This chapter clarifies the distinct challenges associated with deploying LLMs in high-stakes legal applications, with a particular emphasis on contract clause generation. Principal concerns encompass adapting to evolving legal landscapes across jurisdictions, ensuring data privacy and security, addressing biases (e.g., gender stereotypes, jurisdictional inclinations), balancing automation with human oversight, standardizing language while maintaining flexibility, managing multi-jurisdictional complexities, and addressing issues such as accountability for errors. To mitigate these limitations, we propose a comprehensive use-case context-specific evaluation framework, CLAUSE, for contract clause generators. This framework transcends traditional accuracy metrics, evaluating solutions across six critical dimensions: (1) Compliance and Jurisdictional Adaptability, (2) Legal Competence and Reasoning, (3) Accuracy, Reliability, and Trustworthiness, (4) Understanding Context, (5) Structured Contract Elements Handling, and (6) Ethics, Privacy, and Accountability. The CLAUSE framework underscores the essential role of rigorous human-centric evaluation and continuous oversight for the safe, effective, and responsible integration of LLMs into legal practice, thereby ensuring trustworthy AI for evidentiary use. © 2026 selection and editorial matter, Edited by Sarfaraz Ahmed Khan, Lovely Dasgupta, Saptarshi Ghosh and Kripabandhu Ghosh; individual chapters, the contributors.
A3: R0002 | B3: Scopus | C3: 2-s2.0-105026283627 | D3: Conversational Agents: From RAG to LTM | E3: Zhang D.; Feng Y.; Liu H.; Sun C.; Luo J.; Chen X.; Li X. | F3: 2025 | G3: SIGIR-AP 2025 - Proceedings of the 2025 Annual International ACM SIGIR Conference on Research and Development in Information Retrieval in the Asia Pacific Region | H3: Conference paper | I3: 10.1145/3767695.3769671 | M3: Large Language Models (LLMs) have significantly advanced Artificial Intelligence (AI), demonstrating impressive capabilities in language understanding, reasoning, and generation. However, their fixed context windows fundamentally limit their utility in sustained, complex human-computer interactions, leading to issues such as forgetting previous turns, lacking consistent personas, and an inability to perform long-horizon reasoning. While Retrieval-Augmented Generation (RAG) offers a promising solution by externalizing knowledge and providing LLMs with relevant information from external corpora, its traditional static retrieve-then-generate pipeline often struggles with dynamic knowledge integration, introduces noise, and overlooks structural relationships. This tutorial introduces the evolution from traditional RAG to advanced Long-Term Memory (LTM) mechanisms that equip LLM-based conversational agents with human-like memory capabilities. We will explore various LTM architectures, including textual, graph-based, and parametric memory, detailing their forms, operations (such as dynamic indexing, retrieval, updating, and consolidation), and multimodal integration strategies. The tutorial will cover cutting-edge systems (like Mem0), illustrating how they enable agents to maintain coherent conversations, personalize interactions, and perform complex reasoning over extended periods. We will also delve into evaluation benchmarks (e.g., LoCoMo and ZH-4O) as well as metrics that comprehensively assess these long-term memory capabilities. Finally, we will discuss current limitations and promising future research directions, particularly focusing on AI self-evolution, multimodal memory, and ethical considerations. This tutorial aims to provide a comprehensive understanding for researchers and practitioners interested in building the next generation of intelligent, memory-aware conversational AI agents. © 2025 Owner/Author.
A4: R0003 | B4: Scopus | C4: 2-s2.0-85204632333 | D4: Large Language Models in Modern Forensic Investigations: Harnessing the Power of Generative Artificial Intelligence in Crime Resolution and Suspect Identification | E4: Nikolakopoulos A.; Evangelatos S.; Veroni E.; Chasapas K.; Gousetis N.; Apostolaras A.; Nikolopoulos C.D.; Korakis T. | F4: 2024 | G4: EEITE 2024 - Proceedings of 2024 5th International Conference in Electronic Engineering, Information Technology and Education | H4: Conference paper | I4: 10.1109/eeite61750.2024.10654427 | M4: Large Language Models (LLMs) have recently captured the attention of the scientific c ommunity. S ince t he global launch of LLM-based chatbots in late 2022, the field h as witnessed a rapid increase in interest from researchers, technology providers and citizens alike. With its wide-ranging applicability, Generative Artificial I ntelligence (GenAI) h as t he p otential to impact various aspects of society, from improving communication and accessibility to transforming industries such as healthcare, education and security. More specifically, in the field of Forensic Science, LLMs could offer significant b enefits as sisting Law Enforcement Agencies (LEAs) and Forensic Practitioners in crime investigations. This paper proposes the implementation of a Retrieval Augmented Generation (RAG) LLM, trained with criminology data, to provide swift and actionable insights into specific incidents, thereby enhancing Forensic Data Analysis and facilitating the daily operations of LEAs. © 2024 IEEE.
A5: R0004 | B5: Scopus | C5: 2-s2.0-105048451032 | D5: Ontology-Driven Legal Rule Auditor for Secure, Trustworthy, and Governed RAG Systems | E5: Akremi A. | F5: 2026 | G5: Computers | H5: Article | I5: 10.3390/computers15080471 | M5: Large Language Models (LLMs) have significant potential in regulated domains such as law, healthcare, and compliance, where users need help interpreting complex rules and documents. However, these domains also make the risks of Large Language Models especially serious: a system may hallucinate legal authority, rely on outdated rules, mix jurisdictions, or expose sensitive information. Retrieval-Augmented Generation (RAG) reduces these risks by grounding the model’s answer in a curated document corpus, but standard RAG still does not guarantee that the retrieved sources are legally valid, up to date, applicable to the correct jurisdiction, or safe to use. In this paper, we present an ontology-governed approach to legal RAG. The central idea is to use a legal ontology not merely as background knowledge, but as an active control layer. Before retrieval, the ontology filters legal sources by jurisdiction, topic, lifecycle status, and temporal validity. After generation, validation rules check whether the answer is supported by approved evidence, cites valid legal sources, respects jurisdictional boundaries, and avoids unsafe or privacy-violating content. The system also records retrieval, validation, and response-generation steps in an audit trail to support later review. In this way, the proposed Legal Rule Auditor extends Graph RAG from a retrieval-enhancement technique into a governance architecture for legal question answering. Its goal is not simply to improve answer relevance, but to ensure that answers are legally grounded, trusted, current, jurisdictionally appropriate, and traceable. © 2026 by the author.
A6: R0005 | B6: Scopus | C6: 2-s2.0-105042498808 | D6: Harnessing Large Language Models for Next-Generation Artificial Intelligence Applications | E6: Garg N.; Yangalasetty S.; Vangalapat T.; Kumari M.; Basavaraj M.; Gupta M. | F6: 2026 | G6: 2026 2nd International Conference on Big Data and Machine Learning, ICBDML 2026 | H6: Conference paper | I6: 10.1109/icbdml68582.2026.11545008 | M6: Large Language Models (LLMs) usage is the innovation capable of introducing the new generation of the artificial intelligence system with adaptive thinking, multimodal understanding, and grounded knowledge synthesis. Transformer architecture can be developed; less supervised scalable cognitive automation can be enabled by combining developed augmented retrieval-based generation and parameter-efficient tuning. This paper presents a technically valid and conceptually coherent hybrid-grounded LLM model that has cross-modal embedding alignment, external-knowledge recall, symbolical equivalent validation, and, the hallucination-controlled decoding. The methodology guarantees the semantic integrity and logic-sensitive decision-support in the different fields. The experimental evaluation of a group of complex reasoning demonstrates a considerable improvement as the number of perplexities was decreased to 7.1 instead of 16.8, the level of overall accuracy was increased by 63.4 to 83.8 percent, and the level of F1-score improved by 65.1 to 85.4. Generative metrics also show a significant improvement as BLEU scores 36.9, ROUGE-L scores 56.4 and exact match scores also goes to 63.2 and expectation calibration error also goes down to 3.6 and hallucination error also drops to 5.1. These findings indicate that grounded LLM design is an experimental catalyst of the future AI ecosystems with central interests on reliability, knowledge validity and high-fidelity reason. © 2026 IEEE.
